Workbook

Sheet Inputs_Scenarios
A1: Inputs and scenarios
A3: Scenario | C3: Base | E3: Point-in-time cutoff: 2025-08-27. Every driver uses only information filed by then.
A5: days_year | B5: Days per year (annualises a quarter) | C5: 365
A6: q_per_year | B6: Quarters per year | C6: 4
A7: months_year | B7: Months per year | C7: 12
A8: tolerance | B8: Check tolerance, dollars | C8: 0.01
A10: Driver | B10: Description | C10: Base | D10: Upside | E10: Downside | F10: Selected | G10: Tag | H10: Derivation
A11: nrr | B11: Net ARR expansion rate (annual) | C11: 1.19 | D11: 1.21 | E11: 1.17 | F11: =INDEX($C11:$E11,MATCH($C$3,$C$10:$E$10,0)) | G11: [Sourced - SEC Filing] | H11: Disclosed 119% at T0 (Q2 FY26 10-Q). Upside/Downside +/-2pp [Forecast Assumption]: FY25-FY26 disclosures ranged 118-120%.
A12: new_logos | B12: Gross new logos per quarter | C12: 4180.375 | D12: 4798.5 | E12: 3674.5 | F12: =INDEX($C12:$E12,MATCH($C$3,$C$10:$E$10,0)) | G12: [Historical Derived] | H12: Calibrated cohort ledger, trailing 4 quarters to T0: mean (Base), max (Upside), min (Downside). Depends on the [Illustrative] churn rate below.
A13: arr_per_new_logo | B13: New-cohort ARR per new logo ($) | C13: 5102.9708 | D13: 6378.7135 | E13: 3827.2281 | F13: =INDEX($C13:$E13,MATCH($C$3,$C$10:$E$10,0)) | G13: [Historical Derived] | H13: Ledger new-cohort ARR / new logos, trailing 4 quarters to T0 (includes Q1 FY26, near zero). Upside/Downside +/-25% [Forecast Assumption].
A14: churn_q | B14: Gross logo churn per quarter | C14: 0.035 | D14: 0.035 | E14: 0.035 | F14: =INDEX($C14:$E14,MATCH($C$3,$C$10:$E$10,0)) | G14: [Illustrative] | H14: Not disclosed. Same rate as the calibrated cohort ledger; affects logos, not ARR.
A15: ea_yoy | B15: Other subscription (EA) revenue growth, YoY | C15: 0.098724966 | D15: 0.14872497 | E15: 0.048724966 | F15: =INDEX($C15:$E15,MATCH($C$3,$C$10:$E$10,0)) | G15: [Historical Derived] | H15: Trailing-12-month EA revenue growth at T0; applied to the same quarter a year earlier, which keeps the seasonality of upfront term-license revenue. Upside/Downside +/-5pp [Forecast Assumption].
A16: svc_yoy | B16: Services revenue growth, YoY | C16: 0.28014956 | D16: 0.33014956 | E16: 0.23014956 | F16: =INDEX($C16:$E16,MATCH($C$3,$C$10:$E$10,0)) | G16: [Historical Derived] | H16: Trailing-4-quarter growth vs the prior four quarters. +/-5pp band.
A17: sub_gm | B17: Subscription gross margin (GAAP) | C17: 0.76554898 | D17: 0.77554898 | E17: 0.75554898 | F17: =INDEX($C17:$E17,MATCH($C$3,$C$10:$E$10,0)) | G17: [Historical Derived] | H17: Trailing 4 quarters to T0. +/-1pp band.
A18: svc_gm | B18: Services gross margin (GAAP) | C18: -0.55098573 | D18: -0.55098573 | E18: -0.55098573 | F18: =INDEX($C18:$E18,MATCH($C$3,$C$10:$E$10,0)) | G18: [Historical Derived] | H18: Trailing 4 quarters to T0 (negative: services are priced to drive subscription).
A19: net_hires_q | B19: Net hires per quarter | C19: 130.25 | D19: 130.25 | E19: 130.25 | F19: =INDEX($C19:$E19,MATCH($C$3,$C$10:$E$10,0)) | G19: [Historical Derived] | H19: Quarterly pace over the 4 quarters to T0, from headcount interpolated between 10-K year-end counts and extended past January 2025 at the FY25 pace [Estimated].
A20: amort_q | B20: Amortization of intangibles per quarter ($) | C20: 3800000 | D20: 3800000 | E20: 3800000 | F20: =INDEX($C20:$E20,MATCH($C$3,$C$10:$E$10,0)) | G20: [Historical Derived] | H20: Held at the T0 quarter's level.
A21: cph_growth_rnd | B21: R&D: non-GAAP spend per employee, growth per quarter | C21: 0.0086822108 | D21: 0.0086822108 | E21: 0.0086822108 | F21: =INDEX($C21:$E21,MATCH($C$3,$C$10:$E$10,0)) | G21: [Historical Derived] | H21: Compound quarterly growth over the 4 quarters to T0.
A22: sbc_pct_rnd | B22: R&D: stock-based compensation, % of revenue | C22: 0.11609651 | D22: 0.11609651 | E22: 0.11609651 | F22: =INDEX($C22:$E22,MATCH($C$3,$C$10:$E$10,0)) | G22: [Historical Derived] | H22: Trailing 4 quarters to T0.
... A32: fcf_conv_q4 | B32: FCF / non-GAAP operating income, fiscal Q4 | C32: 0.22999625 | D32: 0.22999625 | E32: 0.22999625 | F32: =INDEX($C32:$E32,MATCH($C$3,$C$10:$E$10,0)) | G32: [Historical Derived] | H32: Ratio in Q4 FY25, the latest Q4 known at the cutoff.
A34: GTM capital-allocation case (Unit_Economics_ROI); flat across scenarios
A35: roi_n_ae | B35: A. Incremental Enterprise AEs hired | C35: 30 | D35: 30 | E35: 30 | F35: =INDEX($C35:$E35,MATCH($C$3,$C$10:$E$10,0)) | G35: [Illustrative] | H35: Size of the hiring bet being evaluated.
A36: roi_ae_cost | B36: A. Fully loaded cost per AE, annual ($) | C36: 350000 | D36: 350000 | E36: 350000 | F36: =INDEX($C36:$E36,MATCH($C$3,$C$10:$E$10,0)) | G36: [Illustrative] | H36: Salary, benefits, T&E; excludes commission.
A37: roi_support_pct | B37: A. Support overhead (SEs, managers), % of AE cost | C37: 0.3 | D37: 0.3 | E37: 0.3 | F37: =INDEX($C37:$E37,MATCH($C$3,$C$10:$E$10,0)) | G37: [Illustrative]
A38: roi_quota | B38: A. Annual quota, new ARR per ramped AE ($) | C38: 1000000 | D38: 1000000 | E38: 1000000 | F38: =INDEX($C38:$E38,MATCH($C$3,$C$10:$E$10,0)) | G38: [Illustrative]
A39: roi_attain | B39: A. Quota attainment | C39: 0.7 | D39: 0.7 | E39: 0.7 | F39: =INDEX($C39:$E39,MATCH($C$3,$C$10:$E$10,0)) | G39: [Illustrative]
A40: roi_ramp | B40: A. Ramp to full productivity (months) | C40: 6 | D40: 6 | E40: 6 | F40: =INDEX($C40:$E40,MATCH($C$3,$C$10:$E$10,0)) | G40: [Illustrative] | H40: Linear ramp.
A41: roi_commission | B41: A. Commission, % of booked ARR | C41: 0.1 | D41: 0.1 | E41: 0.1 | F41: =INDEX($C41:$E41,MATCH($C$3,$C$10:$E$10,0)) | G41: [Illustrative] | H41: Paid in the month booked.
A42: roi_target_customers | B42: B. Customers with >$100k ARR (T0) | C42: 2564 | D42: 2564 | E42: 2564 | F42: =INDEX($C42:$E42,MATCH($C$3,$C$10:$E$10,0)) | G42: [Sourced - SEC Filing] | H42: Q2 FY26 10-Q.
A43: roi_attach | B43: B. Attach rate at maturity | C43: 0.15 | D43: 0.15 | E43: 0.15 | F43: =INDEX($C43:$E43,MATCH($C$3,$C$10:$E$10,0)) | G43: [Illustrative] | H43: Share of >$100k customers adopting.
A44: roi_attach_arr | B44: B. Incremental ARR per attaching customer ($) | C44: 40000 | D44: 40000 | E44: 40000 | F44: =INDEX($C44:$E44,MATCH($C$3,$C$10:$E$10,0)) | G44: [Illustrative]
A45: roi_adopt | B45: B. Months to full adoption | C45: 12 | D45: 12 | E45: 12 | F45: =INDEX($C45:$E45,MATCH($C$3,$C$10:$E$10,0)) | G45: [Illustrative] | H45: Linear adoption.
A46: roi_upfront | B46: B. Upfront build cost, month 1 ($) | C46: 15000000 | D46: 15000000 | E46: 15000000 | F46: =INDEX($C46:$E46,MATCH($C$3,$C$10:$E$10,0)) | G46: [Illustrative]
A47: roi_run_cost | B47: B. Ongoing cost per month ($) | C47: 500000 | D47: 500000 | E47: 500000 | F47: =INDEX($C47:$E47,MATCH($C$3,$C$10:$E$10,0)) | G47: [Illustrative]
A48: roi_nrr | B48: Both: net expansion of the new ARR (annual) | C48: 1.19 | D48: 1.19 | E48: 1.19 | F48: =INDEX($C48:$E48,MATCH($C$3,$C$10:$E$10,0)) | G48: [Sourced - SEC Filing] | H48: Disclosed net ARR expansion rate at T0.
A49: roi_gm | B49: Both: non-GAAP subscription gross margin | C49: 0.78096231 | D49: 0.78096231 | E49: 0.78096231 | F49: =INDEX($C49:$E49,MATCH($C$3,$C$10:$E$10,0)) | G49: [Historical Derived] | H49: Trailing 4 quarters to T0.
A50: roi_discount | B50: Both: discount rate (annual) | C50: 0.1 | D50: 0.1 | E50: 0.1 | F50: =INDEX($C50:$E50,MATCH($C$3,$C$10:$E$10,0)) | G50: [Illustrative] | H50: Hurdle rate, not a WACC estimate.
A52: Damped-trend baseline (BvA scorecard, section E); flat across scenarios
A53: dt_alpha | B53: Level smoothing (alpha) | C53: 0.25 | D53: 0.25 | E53: 0.25 | F53: =INDEX($C53:$E53,MATCH($C$3,$C$10:$E$10,0)) | G53: [Historical Derived] | H53: Grid search on quarterly revenue to T0, minimising one-step-ahead squared error.
A54: dt_beta | B54: Trend smoothing (beta) | C54: 0.5 | D54: 0.5 | E54: 0.5 | F54: =INDEX($C54:$E54,MATCH($C$3,$C$10:$E$10,0)) | G54: [Historical Derived] | H54: Grid search on quarterly revenue to T0, minimising one-step-ahead squared error.
...

Sheet Cohort_ARR_Build
A1: Cohort and ARR build [Calibrated Synthetic Cohort Panel for history]
B2: Fiscal label | D2: Q4 FY22 | E2: Q1 FY23 | F2: Q2 FY23 | G2: Q3 FY23 | H2: Q4 FY23 | I2: Q1 FY24 | J2: Q2 FY24 | K2: Q3 FY24 | L2: Q4 FY24 | M2: Q1 FY25 | N2: Q2 FY25 | O2: Q3 FY25 | P2: Q4 FY25 | Q2: Q1 FY26 | R2: Q2 FY26 | S2: Q3 FY26 | T2: Q4 FY26 | U2: Q1 FY27 | V2: Q2 FY27
B3: Period end | D3: 2022-01-31 | E3: 2022-04-30 | F3: 2022-07-31 | G3: 2022-10-31 | H3: 2023-01-31 | I3: 2023-04-30 | J3: 2023-07-31 | K3: 2023-10-31 | L3: 2024-01-31 | M3: 2024-04-30 | N3: 2024-07-31 | O3: 2024-10-31 | P3: 2025-01-31 | Q3: 2025-04-30 | R3: 2025-07-31 | S3: 2025-10-31 | T3: 2026-01-31 | U3: 2026-04-30 | V3: 2026-07-31
B4: Kind | D4: Actual | E4: Actual | F4: Actual | G4: Actual | H4: Actual | I4: Actual | J4: Actual | K4: Actual | L4: Actual | M4: Actual | N4: Actual | O4: Actual | P4: Actual | Q4: Actual | R4: Actual | S4: Forecast | T4: Forecast | U4: Forecast | V4: Forecast
B5: Days | D5: 92 | E5: 89 | F5: 92 | G5: 92 | H5: 92 | I5: 89 | J5: 92 | K5: 92 | L5: 92 | M5: 90 | N5: 92 | O5: 92 | P5: 92 | Q5: 89 | R5: 92 | S5: 92 | T5: 92 | U5: 89 | V5: 92
B6: Fiscal q | D6: 4 | E6: 1 | F6: 2 | G6: 3 | H6: 4 | I6: 1 | J6: 2 | K6: 3 | L6: 4 | M6: 1 | N6: 2 | O6: 3 | P6: 4 | Q6: 1 | R6: 2 | S6: 3 | T6: 4 | U6: 1 | V6: 2
A8: customers | B8: Total customers (period end) | C8: [Sourced - SEC Filing] history | G8: 39100 | H8: 40800 | I8: 43100 | J8: 45000 | K8: 46400 | L8: 47800 | M8: 49200 | N8: 50700 | O8: 52600 | P8: 54500 | Q8: 57100 | R8: 59900 | S8: =R8*(1-Inputs_Scenarios!$F$14)+Inputs_Scenarios!$F$12 | T8: =S8*(1-Inputs_Scenarios!$F$14)+Inputs_Scenarios!$F$12 | U8: =T8*(1-Inputs_Scenarios!$F$14)+Inputs_Scenarios!$F$12 | V8: =U8*(1-Inputs_Scenarios!$F$14)+Inputs_Scenarios!$F$12
A9: churned_logos | B9: Churned logos | C9: [Illustrative] rate | S9: =R8*Inputs_Scenarios!$F$14 | T9: =S8*Inputs_Scenarios!$F$14 | U9: =T8*Inputs_Scenarios!$F$14 | V9: =U8*Inputs_Scenarios!$F$14
A10: new_logos | B10: Gross new logos | C10: [Calibrated Synthetic] history; [Forecast Assumption] | H10: 3068.5 | I10: 3728 | J10: 3408.5 | K10: 2975 | L10: 3024 | M10: 3073 | N10: 3222 | O10: 3674.5 | P10: 3741 | Q10: 4507.5 | R10: 4798.5 | S10: =Inputs_Scenarios!$F$12 | T10: =Inputs_Scenarios!$F$12 | U10: =Inputs_Scenarios!$F$12 | V10: =Inputs_Scenarios!$F$12
A11: ea | B11: Other subscription (EA) revenue | D11: ='Operating_Model'!D9 | E11: ='Operating_Model'!E9 | F11: ='Operating_Model'!F9 | G11: ='Operating_Model'!G9 | H11: ='Operating_Model'!H9 | I11: ='Operating_Model'!I9 | J11: ='Operating_Model'!J9 | K11: ='Operating_Model'!K9 | ... V11: ='Operating_Model'!V9
A12: ea_ttm | B12: EA revenue, trailing 4 quarters | G12: =SUM('Operating_Model'!D9:G9) | H12: =SUM('Operating_Model'!E9:H9) | I12: =SUM('Operating_Model'!F9:I9) | J12: =SUM('Operating_Model'!G9:J9) | K12: =SUM('Operating_Model'!H9:K9) | L12: =SUM('Operating_Model'!I9:L9) | M12: =SUM('Operating_Model'!J9:M9) | N12: =SUM('Operating_Model'!K9:N9) | ... V12: =SUM('Operating_Model'!S9:V9)
A13: arr_existing | B13: ARR from existing customers | S13: =R15*Inputs_Scenarios!$F$11^(1/Inputs_Scenarios!$C$6) | T13: =S15*Inputs_Scenarios!$F$11^(1/Inputs_Scenarios!$C$6) | U13: =T15*Inputs_Scenarios!$F$11^(1/Inputs_Scenarios!$C$6) | V13: =U15*Inputs_Scenarios!$F$11^(1/Inputs_Scenarios!$C$6)
A14: arr_new | B14: ARR from new logos | S14: =Inputs_Scenarios!$F$12*Inputs_Scenarios!$F$13 | T14: =Inputs_Scenarios!$F$12*Inputs_Scenarios!$F$13 | U14: =Inputs_Scenarios!$F$12*Inputs_Scenarios!$F$13 | V14: =Inputs_Scenarios!$F$12*Inputs_Scenarios!$F$13
A15: arr | B15: ARR proxy (Atlas annualised + EA trailing 4Q) | C15: [Historical Derived] proxy | G15: ='Operating_Model'!G8*Inputs_Scenarios!$C$5/G5+G12 | H15: ='Operating_Model'!H8*Inputs_Scenarios!$C$5/H5+H12 | I15: ='Operating_Model'!I8*Inputs_Scenarios!$C$5/I5+I12 | J15: ='Operating_Model'!J8*Inputs_Scenarios!$C$5/J5+J12 | K15: ='Operating_Model'!K8*Inputs_Scenarios!$C$5/K5+K12 | L15: ='Operating_Model'!L8*Inputs_Scenarios!$C$5/L5+L12 | M15: ='Operating_Model'!M8*Inputs_Scenarios!$C$5/M5+M12 | N15: ='Operating_Model'!N8*Inputs_Scenarios!$C$5/N5+N12 | ... R15: ='Operating_Model'!R8*Inputs_Scenarios!$C$5/R5+R12 | S15: =S13+S14 | T15: =T13+T14 | U15: =U13+U14 | V15: =V13+V14
A16: atlas_run_rate | B16: Atlas annual run-rate (ARR - EA trailing 4Q) | G16: =G15-G12 | H16: =H15-H12 | I16: =I15-I12 | J16: =J15-J12 | K16: =K15-K12 | L16: =L15-L12 | M16: =M15-M12 | N16: =N15-N12 | ... V16: =V15-V12
A17: atlas_rev | B17: Atlas revenue (run-rate x days / 365) | D17: ='Operating_Model'!D8 | E17: ='Operating_Model'!E8 | F17: ='Operating_Model'!F8 | G17: ='Operating_Model'!G8 | H17: ='Operating_Model'!H8 | I17: ='Operating_Model'!I8 | J17: ='Operating_Model'!J8 | K17: ='Operating_Model'!K8 | ... R17: ='Operating_Model'!R8 | S17: =S16*S5/Inputs_Scenarios!$C$5 | T17: =T16*T5/Inputs_Scenarios!$C$5 | U17: =U16*U5/Inputs_Scenarios!$C$5 | V17: =V16*V5/Inputs_Scenarios!$C$5
A18: nrr | B18: Net ARR expansion rate (disclosed / driver) | C18: [Sourced - SEC Filing] history | F18: 1.2 | G18: 1.2 | H18: 1.2 | I18: 1.2 | J18: 1.2 | K18: 1.2 | L18: 1.2 | M18: 1.2 | N18: 1.19 | O18: 1.2 | P18: 1.18 | Q18: 1.19 | R18: 1.19 | S18: =Inputs_Scenarios!$F$11 | T18: =Inputs_Scenarios!$F$11 | U18: =Inputs_Scenarios!$F$11 | V18: =Inputs_Scenarios!$F$11
A19: arr_ledger | B19: ARR proxy per cohort ledger (check) | C19: [Calibrated Synthetic Cohort Panel] | G19: 1.2531642e+09 | H19: 1.3533877e+09 | I19: 1.4142977e+09 | J19: 1.5433711e+09 | K19: 1643229000 | L19: 1.7656768e+09 | M19: 1.8009144e+09 | N19: 1.8577594e+09 | O19: 1.966814e+09 | P19: 2.0821618e+09 | Q19: 2.1748071e+09 | R19: 2.3020298e+09

Sheet Headcount_Opex_Build
A1: Headcount and operating expense build
B2: Fiscal label | D2: Q4 FY22 | E2: Q1 FY23 | F2: Q2 FY23 | G2: Q3 FY23 | H2: Q4 FY23 | I2: Q1 FY24 | J2: Q2 FY24 | K2: Q3 FY24 | L2: Q4 FY24 | M2: Q1 FY25 | N2: Q2 FY25 | O2: Q3 FY25 | P2: Q4 FY25 | Q2: Q1 FY26 | R2: Q2 FY26 | S2: Q3 FY26 | T2: Q4 FY26 | U2: Q1 FY27 | V2: Q2 FY27
B3: Period end | D3: 2022-01-31 | E3: 2022-04-30 | F3: 2022-07-31 | G3: 2022-10-31 | H3: 2023-01-31 | I3: 2023-04-30 | J3: 2023-07-31 | K3: 2023-10-31 | L3: 2024-01-31 | M3: 2024-04-30 | N3: 2024-07-31 | O3: 2024-10-31 | P3: 2025-01-31 | Q3: 2025-04-30 | R3: 2025-07-31 | S3: 2025-10-31 | T3: 2026-01-31 | U3: 2026-04-30 | V3: 2026-07-31
B4: Kind | D4: Actual | E4: Actual | F4: Actual | G4: Actual | H4: Actual | I4: Actual | J4: Actual | K4: Actual | L4: Actual | M4: Actual | N4: Actual | O4: Actual | P4: Actual | Q4: Actual | R4: Actual | S4: Forecast | T4: Forecast | U4: Forecast | V4: Forecast
B5: Days | D5: 92 | E5: 89 | F5: 92 | G5: 92 | H5: 92 | I5: 89 | J5: 92 | K5: 92 | L5: 92 | M5: 90 | N5: 92 | O5: 92 | P5: 92 | Q5: 89 | R5: 92 | S5: 92 | T5: 92 | U5: 89 | V5: 92
B6: Fiscal q | D6: 4 | E6: 1 | F6: 2 | G6: 3 | H6: 4 | I6: 1 | J6: 2 | K6: 3 | L6: 4 | M6: 1 | N6: 2 | O6: 3 | P6: 4 | Q6: 1 | R6: 2 | S6: 3 | T6: 4 | U6: 1 | V6: 2
A8: headcount | B8: Employees (period end) | C8: see basis row | H8: 4619 | I8: 4723.5 | J8: 4828 | K8: 4932.5 | L8: 5037 | M8: 5167.25 | N8: 5297.5 | O8: 5427.75 | P8: 5558 | Q8: 5688.25 | R8: 5818.5 | S8: =R8+Inputs_Scenarios!$F$19 | T8: =S8+Inputs_Scenarios!$F$19 | U8: =T8+Inputs_Scenarios!$F$19 | V8: =U8+Inputs_Scenarios!$F$19
A9: hc_basis | B9: Headcount basis | H9: [Sourced - SEC Filing] | I9: [Interpolated] | J9: [Interpolated] | K9: [Interpolated] | L9: [Sourced - SEC Filing] | M9: [Interpolated] | N9: [Interpolated] | O9: [Interpolated] | P9: [Sourced - SEC Filing] | Q9: [Estimated] | R9: [Estimated]
A10: ng_rnd | B10: R&D: non-GAAP spend | D10: ='Operating_Model'!D24-'Operating_Model'!D21 | E10: ='Operating_Model'!E24-'Operating_Model'!E21 | F10: ='Operating_Model'!F24-'Operating_Model'!F21 | G10: ='Operating_Model'!G24-'Operating_Model'!G21 | H10: ='Operating_Model'!H24-'Operating_Model'!H21 | I10: ='Operating_Model'!I24-'Operating_Model'!I21 | J10: ='Operating_Model'!J24-'Operating_Model'!J21 | K10: ='Operating_Model'!K24-'Operating_Model'!K21 | ... R10: ='Operating_Model'!R24-'Operating_Model'!R21 | S10: =S8*S11 | T10: =T8*T11 | U10: =U8*U11 | V10: =V8*V11
A11: cph_rnd | B11: R&D: non-GAAP spend per employee (quarter) | G11: =IF(G8="","",G10/G8) | H11: =IF(H8="","",H10/H8) | I11: =IF(I8="","",I10/I8) | J11: =IF(J8="","",J10/J8) | K11: =IF(K8="","",K10/K8) | L11: =IF(L8="","",L10/L8) | M11: =IF(M8="","",M10/M8) | N11: =IF(N8="","",N10/N8) | ... R11: =IF(R8="","",R10/R8) | S11: =R11*(1+Inputs_Scenarios!$F$21) | T11: =S11*(1+Inputs_Scenarios!$F$21) | U11: =T11*(1+Inputs_Scenarios!$F$21) | V11: =U11*(1+Inputs_Scenarios!$F$21)
A12: ng_snm | B12: Sales and marketing: non-GAAP spend | D12: ='Operating_Model'!D25-'Operating_Model'!D22 | E12: ='Operating_Model'!E25-'Operating_Model'!E22 | F12: ='Operating_Model'!F25-'Operating_Model'!F22 | G12: ='Operating_Model'!G25-'Operating_Model'!G22 | H12: ='Operating_Model'!H25-'Operating_Model'!H22 | I12: ='Operating_Model'!I25-'Operating_Model'!I22 | J12: ='Operating_Model'!J25-'Operating_Model'!J22 | K12: ='Operating_Model'!K25-'Operating_Model'!K22 | ... R12: ='Operating_Model'!R25-'Operating_Model'!R22 | S12: =S8*S13 | T12: =T8*T13 | U12: =U8*U13 | V12: =V8*V13
A13: cph_snm | B13: Sales and marketing: non-GAAP spend per employee (quarter) | G13: =IF(G8="","",G12/G8) | H13: =IF(H8="","",H12/H8) | I13: =IF(I8="","",I12/I8) | J13: =IF(J8="","",J12/J8) | K13: =IF(K8="","",K12/K8) | L13: =IF(L8="","",L12/L8) | M13: =IF(M8="","",M12/M8) | N13: =IF(N8="","",N12/N8) | ... R13: =IF(R8="","",R12/R8) | S13: =R13*(1+Inputs_Scenarios!$F$23) | T13: =S13*(1+Inputs_Scenarios!$F$23) | U13: =T13*(1+Inputs_Scenarios!$F$23) | V13: =U13*(1+Inputs_Scenarios!$F$23)
A14: ng_gna | B14: General and administrative: non-GAAP spend | D14: ='Operating_Model'!D26-'Operating_Model'!D23 | E14: ='Operating_Model'!E26-'Operating_Model'!E23 | F14: ='Operating_Model'!F26-'Operating_Model'!F23 | G14: ='Operating_Model'!G26-'Operating_Model'!G23 | H14: ='Operating_Model'!H26-'Operating_Model'!H23 | I14: ='Operating_Model'!I26-'Operating_Model'!I23 | J14: ='Operating_Model'!J26-'Operating_Model'!J23 | K14: ='Operating_Model'!K26-'Operating_Model'!K23 | ... R14: ='Operating_Model'!R26-'Operating_Model'!R23 | S14: =S8*S15 | T14: =T8*T15 | U14: =U8*U15 | V14: =V8*V15
A15: cph_gna | B15: General and administrative: non-GAAP spend per employee (quarter) | G15: =IF(G8="","",G14/G8) | H15: =IF(H8="","",H14/H8) | I15: =IF(I8="","",I14/I8) | J15: =IF(J8="","",J14/J8) | K15: =IF(K8="","",K14/K8) | L15: =IF(L8="","",L14/L8) | M15: =IF(M8="","",M14/M8) | N15: =IF(N8="","",N14/N8) | ... R15: =IF(R8="","",R14/R8) | S15: =R15*(1+Inputs_Scenarios!$F$25) | T15: =S15*(1+Inputs_Scenarios!$F$25) | U15: =T15*(1+Inputs_Scenarios!$F$25) | V15: =U15*(1+Inputs_Scenarios!$F$25)
A16: ng_total | B16: Non-GAAP operating expenses | D16: =D10+D12+D14 | E16: =E10+E12+E14 | F16: =F10+F12+F14 | G16: =G10+G12+G14 | H16: =H10+H12+H14 | I16: =I10+I12+I14 | J16: =J10+J12+J14 | K16: =K10+K12+K14 | ... V16: =V10+V12+V14

Sheet Operating_Model
A1: Operating model: income statement and free cash flow (USD)
B2: Fiscal label | D2: Q4 FY22 | E2: Q1 FY23 | F2: Q2 FY23 | G2: Q3 FY23 | H2: Q4 FY23 | I2: Q1 FY24 | J2: Q2 FY24 | K2: Q3 FY24 | L2: Q4 FY24 | M2: Q1 FY25 | N2: Q2 FY25 | O2: Q3 FY25 | P2: Q4 FY25 | Q2: Q1 FY26 | R2: Q2 FY26 | S2: Q3 FY26 | T2: Q4 FY26 | U2: Q1 FY27 | V2: Q2 FY27
B3: Period end | D3: 2022-01-31 | E3: 2022-04-30 | F3: 2022-07-31 | G3: 2022-10-31 | H3: 2023-01-31 | I3: 2023-04-30 | J3: 2023-07-31 | K3: 2023-10-31 | L3: 2024-01-31 | M3: 2024-04-30 | N3: 2024-07-31 | O3: 2024-10-31 | P3: 2025-01-31 | Q3: 2025-04-30 | R3: 2025-07-31 | S3: 2025-10-31 | T3: 2026-01-31 | U3: 2026-04-30 | V3: 2026-07-31
B4: Kind | D4: Actual | E4: Actual | F4: Actual | G4: Actual | H4: Actual | I4: Actual | J4: Actual | K4: Actual | L4: Actual | M4: Actual | N4: Actual | O4: Actual | P4: Actual | Q4: Actual | R4: Actual | S4: Forecast | T4: Forecast | U4: Forecast | V4: Forecast
B5: Days | D5: 92 | E5: 89 | F5: 92 | G5: 92 | H5: 92 | I5: 89 | J5: 92 | K5: 92 | L5: 92 | M5: 90 | N5: 92 | O5: 92 | P5: 92 | Q5: 89 | R5: 92 | S5: 92 | T5: 92 | U5: 89 | V5: 92
B6: Fiscal q | D6: 4 | E6: 1 | F6: 2 | G6: 3 | H6: 4 | I6: 1 | J6: 2 | K6: 3 | L6: 4 | M6: 1 | N6: 2 | O6: 3 | P6: 4 | Q6: 1 | R6: 2 | S6: 3 | T6: 4 | U6: 1 | V6: 2
A8: atlas | B8: Atlas-related subscription revenue | C8: [Sourced - SEC Filing] history | D8: 155897000 | E8: 169995000 | F8: 193354000 | G8: 211378000 | H8: 233536000 | I8: 237756000 | J8: 267258000 | K8: 286856000 | L8: 313481000 | M8: 313855000 | N8: 339683000 | O8: 362604000 | P8: 389042000 | Q8: 395893000 | R8: 438970000 | S8: ='Cohort_ARR_Build'!S17 | T8: ='Cohort_ARR_Build'!T17 | U8: ='Cohort_ARR_Build'!U17 | V8: ='Cohort_ARR_Build'!V17
A9: ea | B9: Other subscription revenue (EA) | C9: [Sourced - SEC Filing] history | D9: 102328000 | E9: 104586000 | F9: 98253000 | G9: 109378000 | H9: 114642000 | I9: 116958000 | J9: 142076000 | K9: 131483000 | L9: 131458000 | M9: 123041000 | N9: 124122000 | O9: 149601000 | P9: 141916000 | Q9: 135562000 | R9: 133385000 | S9: =O9*(1+Inputs_Scenarios!$F$15) | T9: =P9*(1+Inputs_Scenarios!$F$15) | U9: =Q9*(1+Inputs_Scenarios!$F$15) | V9: =R9*(1+Inputs_Scenarios!$F$15)
A10: sub | B10: Subscription revenue | D10: =D8+D9 | E10: =E8+E9 | F10: =F8+F9 | G10: =G8+G9 | H10: =H8+H9 | I10: =I8+I9 | J10: =J8+J9 | K10: =K8+K9 | ... V10: =V8+V9
A11: svc | B11: Services revenue | C11: [Sourced - SEC Filing] history | D11: 8269000 | E11: 10866000 | F11: 12053000 | G11: 12865000 | H11: 13134000 | I11: 13566000 | J11: 14457000 | K11: 14599000 | L11: 13063000 | M11: 13665000 | N11: 14304000 | O11: 17170000 | P11: 17440000 | Q11: 17559000 | R11: 19047000 | S11: =O11*(1+Inputs_Scenarios!$F$16) | T11: =P11*(1+Inputs_Scenarios!$F$16) | U11: =Q11*(1+Inputs_Scenarios!$F$16) | V11: =R11*(1+Inputs_Scenarios!$F$16)
A12: revenue | B12: Total revenue | D12: =D10+D11 | E12: =E10+E11 | F12: =F10+F11 | G12: =G10+G11 | H12: =H10+H11 | I12: =I10+I11 | J12: =J10+J11 | K12: =K10+K11 | ... V12: =V10+V11
A13: rev_yoy | B13: Revenue growth, YoY | H13: =H12/D12-1 | I13: =I12/E12-1 | J13: =J12/F12-1 | K13: =K12/G12-1 | L13: =L12/H12-1 | M13: =M12/I12-1 | N13: =N12/J12-1 | O13: =O12/K12-1 | ... V13: =V12/R12-1
A14: cost_sub | B14: Cost of subscription | D14: 64166000 | E14: 64569000 | F14: 71435000 | G14: 77150000 | H14: 71429000 | I14: 78173000 | J14: 84822000 | K14: 87954000 | L14: 94284000 | M14: 100762000 | N14: 106816000 | O14: 111150000 | P14: 122676000 | Q14: 129585000 | R14: 139949000 | S14: =S10*(1-Inputs_Scenarios!$F$17) | T14: =T10*(1-Inputs_Scenarios!$F$17) | U14: =U10*(1-Inputs_Scenarios!$F$17) | V14: =V10*(1-Inputs_Scenarios!$F$17)
A15: cost_svc | B15: Cost of services | D15: 11632000 | E15: 13646000 | F15: 16842000 | G15: 16502000 | H15: 17731000 | I15: 19276000 | J15: 20515000 | K15: 19104000 | L15: 20357000 | M15: 21935000 | N15: 21437000 | O15: 24181000 | P15: 26339000 | Q15: 28456000 | R15: 31479000 | S15: =S11*(1-Inputs_Scenarios!$F$18) | T15: =T11*(1-Inputs_Scenarios!$F$18) | U15: =U11*(1-Inputs_Scenarios!$F$18) | V15: =V11*(1-Inputs_Scenarios!$F$18)
A16: cost | B16: Cost of revenue | D16: =D14+D15 | E16: =E14+E15 | F16: =F14+F15 | G16: =G14+G15 | H16: =H14+H15 | I16: =I14+I15 | J16: =J14+J15 | K16: =K14+K15 | ... V16: =V14+V15
A17: gp | B17: Gross profit | D17: =D12-D16 | E17: =E12-E16 | F17: =F12-F16 | G17: =G12-G16 | H17: =H12-H16 | I17: =I12-I16 | J17: =J12-J16 | K17: =K12-K16 | ... V17: =V12-V16
A18: gm | B18: Gross margin | D18: =D17/D12 | E18: =E17/E12 | F18: =F17/F12 | G18: =G17/G12 | H18: =H17/H12 | I18: =I17/I12 | J18: =J17/J12 | K18: =K17/K12 | ... V18: =V17/V12
A19: sbc_cost_subscription | B19: Stock-based compensation in cost subscription | D19: 4065000 | E19: 4467000 | F19: 5009000 | G19: 5016000 | H19: 5190000 | I19: 5514000 | J19: 6075000 | K19: 6018000 | L19: 6070000 | M19: 6163000 | N19: 7519000 | O19: 7884000 | P19: 7982000 | Q19: 8395000 | R19: 8831000 | S19: =S12*Inputs_Scenarios!$F$27 | T19: =T12*Inputs_Scenarios!$F$27 | U19: =U12*Inputs_Scenarios!$F$27 | V19: =V12*Inputs_Scenarios!$F$27
A20: sbc_cost_services | B20: Stock-based compensation in cost services | D20: 1852000 | E20: 2212000 | F20: 2560000 | G20: 2827000 | H20: 2966000 | I20: 2948000 | J20: 3342000 | K20: 3200000 | L20: 3243000 | M20: 3255000 | N20: 3401000 | O20: 3495000 | P20: 3766000 | Q20: 3894000 | R20: 4273000 | S20: =S12*Inputs_Scenarios!$F$28 | T20: =T12*Inputs_Scenarios!$F$28 | U20: =U12*Inputs_Scenarios!$F$28 | V20: =V12*Inputs_Scenarios!$F$28
A21: sbc_rnd | B21: Stock-based compensation in rnd | D21: 31108000 | E21: 35483000 | F21: 40642000 | G21: 41458000 | H21: 41516000 | I21: 44066000 | J21: 48413000 | K21: 50759000 | L21: 55689000 | M21: 55173000 | N21: 55188000 | O21: 57850000 | P21: 58156000 | Q21: 66405000 | R21: 75113000 | S21: =S12*Inputs_Scenarios!$F$22 | T21: =T12*Inputs_Scenarios!$F$22 | U21: =U12*Inputs_Scenarios!$F$22 | V21: =V12*Inputs_Scenarios!$F$22
A22: sbc_snm | B22: Stock-based compensation in snm | D22: 27198000 | E22: 30534000 | F22: 35653000 | G22: 38352000 | H22: 38534000 | I22: 37606000 | J22: 40376000 | K22: 40585000 | L22: 41340000 | M22: 39613000 | N22: 41040000 | O22: 40540000 | P22: 40124000 | Q22: 39102000 | R22: 36265000 | S22: =S12*Inputs_Scenarios!$F$24 | T22: =T12*Inputs_Scenarios!$F$24 | U22: =U12*Inputs_Scenarios!$F$24 | V22: =V12*Inputs_Scenarios!$F$24
A23: sbc_gna | B23: Stock-based compensation in gna | D23: 9519000 | E23: 10870000 | F23: 12690000 | G23: 11545000 | H23: 13930000 | I23: 13821000 | J23: 15106000 | K23: 15267000 | L23: 17469000 | M23: 16559000 | N23: 15275000 | O23: 15943000 | P23: 15014000 | Q23: 14635000 | R23: 15918000 | S23: =S12*Inputs_Scenarios!$F$26 | T23: =T12*Inputs_Scenarios!$F$26 | U23: =U12*Inputs_Scenarios!$F$26 | V23: =V12*Inputs_Scenarios!$F$26
A24: rnd | B24: Research and development | D24: 89417000 | E24: 96372000 | F24: 108037000 | G24: 106392000 | H24: 110891000 | I24: 116817000 | J24: 125420000 | K24: 128150000 | L24: 145553000 | M24: 146060000 | N24: 148967000 | O24: 151410000 | P24: 150400000 | Q24: 168829000 | R24: 181739000 | S24: ='Headcount_Opex_Build'!S10+S21 | T24: ='Headcount_Opex_Build'!T10+T21 | U24: ='Headcount_Opex_Build'!U10+U21 | V24: ='Headcount_Opex_Build'!V10+V21
A25: snm | B25: Sales and marketing | D25: 144263000 | E25: 150268000 | F25: 181598000 | G25: 177419000 | H25: 189916000 | I25: 182733000 | J25: 195934000 | K25: 192977000 | L25: 211116000 | M25: 219444000 | N25: 221539000 | O25: 217954000 | P25: 212211000 | Q25: 220923000 | R25: 244065000 | S25: ='Headcount_Opex_Build'!S12+S22 | T25: ='Headcount_Opex_Build'!T12+T22 | U25: ='Headcount_Opex_Build'!U12+U22 | V25: ='Headcount_Opex_Build'!V12+V22
A26: gna | B26: General and administrative | D26: 35635000 | E26: 36532000 | F26: 40591000 | G26: 39081000 | H26: 44294000 | I26: 39828000 | J26: 46103000 | K26: 49969000 | L26: 57658000 | M26: 60546000 | N26: 50790000 | O26: 52556000 | P26: 55334000 | Q26: 54775000 | R26: 59464000 | S26: ='Headcount_Opex_Build'!S14+S23 | T26: ='Headcount_Opex_Build'!T14+T23 | U26: ='Headcount_Opex_Build'!U14+U23 | V26: ='Headcount_Opex_Build'!V14+V23
A27: opex | B27: Total operating expenses | D27: =D24+D25+D26 | E27: =E24+E25+E26 | F27: =F24+F25+F26 | G27: =G24+G25+G26 | H27: =H24+H25+H26 | I27: =I24+I25+I26 | J27: =J24+J25+J26 | K27: =K24+K25+K26 | ... V27: =V24+V25+V26
A28: op_inc | B28: GAAP operating income (loss) | D28: =D17-D27 | E28: =E17-E27 | F28: =F17-F27 | G28: =G17-G27 | H28: =H17-H27 | I28: =I17-I27 | J28: =J17-J27 | K28: =K17-K27 | ... V28: =V17-V27
A29: op_inc_reported | B29: GAAP operating income, as reported (check) | D29: -78619000 | E29: -75940000 | F29: -114843000 | G29: -82923000 | H29: -72949000 | I29: -68547000 | J29: -49003000 | K29: -45216000 | L29: -70966000 | M29: -98186000 | N29: -71440000 | O29: -27876000 | P29: -18562000 | Q29: -53554000 | R29: -65294000
A30: op_margin | B30: GAAP operating margin | D30: =D28/D12 | E30: =E28/E12 | F30: =F28/F12 | G30: =G28/G12 | H30: =H28/H12 | I30: =I28/I12 | J30: =J28/J12 | K30: =K28/K12 | ... V30: =V28/V12
A31: sbc_total | B31: Stock-based compensation, total | D31: =D19+D20+D21+D22+D23 | E31: =E19+E20+E21+E22+E23 | F31: =F19+F20+F21+F22+F23 | G31: =G19+G20+G21+G22+G23 | H31: =H19+H20+H21+H22+H23 | I31: =I19+I20+I21+I22+I23 | J31: =J19+J20+J21+J22+J23 | K31: =K19+K20+K21+K22+K23 | ... V31: =V19+V20+V21+V22+V23
A32: amort | B32: Amortization of intangibles | D32: 2300000 | E32: 2300000 | F32: 2300000 | G32: 2300000 | H32: 2300000 | I32: 2300000 | J32: 2300000 | K32: 2800000 | L32: 3200000 | M32: 2700000 | N32: 100000 | O32: 200000 | P32: 300000 | Q32: 3100000 | R32: 3800000 | S32: =Inputs_Scenarios!$F$20 | T32: =Inputs_Scenarios!$F$20 | U32: =Inputs_Scenarios!$F$20 | V32: =Inputs_Scenarios!$F$20
A33: ng_op_inc | B33: Non-GAAP operating income (excl. SBC and amortization) | D33: =D28+D31+D32 | E33: =E28+E31+E32 | F33: =F28+F31+F32 | G33: =G28+G31+G32 | H33: =H28+H31+H32 | I33: =I28+I31+I32 | J33: =J28+J31+J32 | K33: =K28+K31+K32 | ... V33: =V28+V31+V32
A34: ng_op_margin | B34: Non-GAAP operating margin | D34: =D33/D12 | E34: =E33/E12 | F34: =F33/F12 | G34: =G33/G12 | H34: =H33/H12 | I34: =I33/I12 | J34: =J33/J12 | K34: =K33/K12 | ... V34: =V33/V12
A35: cfo | B35: Operating cash flow | D35: 22311000 | E35: 11574000 | F35: -44671000 | G35: -5744000 | H35: 25871000 | I35: 53730000 | J35: -25302000 | K35: 38422000 | L35: 54627000 | M35: 63613000 | N35: -1398000 | O35: 37438000 | P35: 50538000 | Q35: 109929000 | R35: 72105000
A36: capex | B36: Capital expenditures | D36: 3556000 | E36: 2538000 | F36: 2614000 | G36: 1381000 | H36: 711000 | I36: 623000 | J36: 635000 | K36: 2078000 | L36: 2738000 | M36: 539000 | N36: 1051000 | O36: 1981000 | P36: 25979000 | Q36: 1611000 | R36: 537000
A37: fcf | B37: Free cash flow | D37: =D35-D36 | E37: =E35-E36 | F37: =F35-F36 | G37: =G35-G36 | H37: =H35-H36 | I37: =I35-I36 | J37: =J35-J36 | K37: =K35-K36 | ... R37: =R35-R36 | S37: =S33*INDEX(Inputs_Scenarios!$F$29:$F$32,S6) | T37: =T33*INDEX(Inputs_Scenarios!$F$29:$F$32,T6) | U37: =U33*INDEX(Inputs_Scenarios!$F$29:$F$32,U6) | V37: =V33*INDEX(Inputs_Scenarios!$F$29:$F$32,V6)
A38: fcf_margin | B38: FCF margin | D38: =D37/D12 | E38: =E37/E12 | F38: =F37/F12 | G38: =G37/G12 | H38: =H37/H12 | I38: =I37/I12 | J38: =J37/J12 | K38: =K37/K12 | ... V38: =V37/V12

Sheet BvA_Variance_Backtest
A1: Budget vs actual: the frozen forecast scored against reported results
B2: Fiscal label | D2: Q4 FY22 | E2: Q1 FY23 | F2: Q2 FY23 | G2: Q3 FY23 | H2: Q4 FY23 | I2: Q1 FY24 | J2: Q2 FY24 | K2: Q3 FY24 | L2: Q4 FY24 | M2: Q1 FY25 | N2: Q2 FY25 | O2: Q3 FY25 | P2: Q4 FY25 | Q2: Q1 FY26 | R2: Q2 FY26 | S2: Q3 FY26 | T2: Q4 FY26 | U2: Q1 FY27 | V2: Q2 FY27 | W2: 4Q
B3: Period end | D3: 2022-01-31 | E3: 2022-04-30 | F3: 2022-07-31 | G3: 2022-10-31 | H3: 2023-01-31 | I3: 2023-04-30 | J3: 2023-07-31 | K3: 2023-10-31 | L3: 2024-01-31 | M3: 2024-04-30 | N3: 2024-07-31 | O3: 2024-10-31 | P3: 2025-01-31 | Q3: 2025-04-30 | R3: 2025-07-31 | S3: 2025-10-31 | T3: 2026-01-31 | U3: 2026-04-30 | V3: 2026-07-31
B4: Kind | D4: Actual | E4: Actual | F4: Actual | G4: Actual | H4: Actual | I4: Actual | J4: Actual | K4: Actual | L4: Actual | M4: Actual | N4: Actual | O4: Actual | P4: Actual | Q4: Actual | R4: Actual | S4: Forecast | T4: Forecast | U4: Forecast | V4: Forecast
B5: Days | D5: 92 | E5: 89 | F5: 92 | G5: 92 | H5: 92 | I5: 89 | J5: 92 | K5: 92 | L5: 92 | M5: 90 | N5: 92 | O5: 92 | P5: 92 | Q5: 89 | R5: 92 | S5: 92 | T5: 92 | U5: 89 | V5: 92
B6: Fiscal q | D6: 4 | E6: 1 | F6: 2 | G6: 3 | H6: 4 | I6: 1 | J6: 2 | K6: 3 | L6: 4 | M6: 1 | N6: 2 | O6: 3 | P6: 4 | Q6: 1 | R6: 2 | S6: 3 | T6: 4 | U6: 1 | V6: 2
A8: h_act | B8: A. Actuals as finally reported (latest filings) [Sourced - SEC Filing]
A9: act_atlas | B9: Atlas-related revenue | S9: 470399000 | T9: 502604000 | U9: 512466000 | V9: 565916000
A10: act_ea | B10: Other subscription revenue (EA) | D10: ='Operating_Model'!D9 | E10: ='Operating_Model'!E9 | F10: ='Operating_Model'!F9 | G10: ='Operating_Model'!G9 | H10: ='Operating_Model'!H9 | I10: ='Operating_Model'!I9 | J10: ='Operating_Model'!J9 | K10: ='Operating_Model'!K9 | ... R10: ='Operating_Model'!R9 | S10: 138668000 | T10: 170496000 | U10: 153672000 | V10: 181231000
A11: act_svc | B11: Services revenue | D11: ='Operating_Model'!D11 | E11: ='Operating_Model'!E11 | F11: ='Operating_Model'!F11 | G11: ='Operating_Model'!G11 | H11: ='Operating_Model'!H11 | I11: ='Operating_Model'!I11 | J11: ='Operating_Model'!J11 | K11: ='Operating_Model'!K11 | ... R11: ='Operating_Model'!R11 | S11: 19242000 | T11: 21972000 | U11: 21478000 | V11: 24626000
A12: act_cost_sub | B12: Cost of subscription | S12: 146921000 | T12: 155076000 | U12: 164907000 | V12: 174251000
A13: act_cost_svc | B13: Cost of services | S13: 32256000 | T13: 32336000 | U13: 26534000 | V13: 27757000
A14: act_sbc_cost_subscription | B14: SBC in cost of subscription | S14: 8990000 | T14: 8444000 | U14: 8888000 | V14: 9205000
A15: act_sbc_cost_services | B15: SBC in cost of services | S15: 4572000 | T15: 4444000 | U15: 2792000 | V15: 3424000
A16: act_rnd | B16: Research and development | S16: 176610000 | T16: 189125000 | U16: 200409000 | V16: 213874000
A17: act_snm | B17: Sales and marketing | S17: 230864000 | T17: 248537000 | U17: 249334000 | V17: 253071000
A18: act_gna | B18: General and administrative | S18: 60082000 | T18: 69694000 | U18: 71236000 | V18: 74420000
A19: act_sbc_rnd | B19: SBC in R&D | S19: 67255000 | T19: 70808000 | U19: 70708000 | V19: 74506000
A20: act_sbc_snm | B20: SBC in S&M | S20: 36965000 | T20: 37454000 | U20: 32681000 | V20: 35722000
A21: act_sbc_gna | B21: SBC in G&A | S21: 15848000 | T21: 22843000 | U21: 22761000 | V21: 26082000
A22: act_amort | B22: Amortization of intangibles | S22: 3800000 | T22: 3900000 | U22: 3700000 | V22: 3800000
A23: act_cfo | B23: Operating cash flow | S23: 143510000 | T23: 179604000 | U23: 201631000 | V23: 141878000
A24: act_capex | B24: Capital expenditures | S24: 1678000 | T24: 1134000 | U24: 2319000 | V24: 2472000
A25: act_customers | B25: Total customers | G25: ='Cohort_ARR_Build'!G8 | H25: ='Cohort_ARR_Build'!H8 | I25: ='Cohort_ARR_Build'!I8 | J25: ='Cohort_ARR_Build'!J8 | K25: ='Cohort_ARR_Build'!K8 | L25: ='Cohort_ARR_Build'!L8 | M25: ='Cohort_ARR_Build'!M8 | N25: ='Cohort_ARR_Build'!N8 | ... R25: ='Cohort_ARR_Build'!R8 | S25: 62500 | T25: 65200 | U25: 67700 | V25: 70600
A26: act_nrr | B26: Net ARR expansion rate | S26: 1.2 | T26: 1.21 | U26: 1.21 | V26: 1.22
A27: act_headcount | B27: Employees | S27: 5616.5 | T27: 5636 | U27: 5655.5 | V27: 5675
A28: act_hc_basis | B28: Headcount basis | S28: [Interpolated] | T28: [Sourced - SEC Filing] | U28: [Estimated] | V28: [Estimated]
A29: act_sub | B29: Subscription revenue | S29: =S9+S10 | T29: =T9+T10 | U29: =U9+U10 | V29: =V9+V10
A30: act_revenue | B30: Total revenue | S30: =S29+S11 | T30: =T29+T11 | U30: =U29+U11 | V30: =V29+V11
A31: act_ea_ttm | B31: EA revenue, trailing 4 quarters | S31: =SUM(P10:S10) | T31: =SUM(Q10:T10) | U31: =SUM(R10:U10) | V31: =SUM(S10:V10)
A32: act_arr | B32: ARR proxy | G32: ='Cohort_ARR_Build'!G15 | H32: ='Cohort_ARR_Build'!H15 | I32: ='Cohort_ARR_Build'!I15 | J32: ='Cohort_ARR_Build'!J15 | K32: ='Cohort_ARR_Build'!K15 | L32: ='Cohort_ARR_Build'!L15 | M32: ='Cohort_ARR_Build'!M15 | N32: ='Cohort_ARR_Build'!N15 | ... R32: ='Cohort_ARR_Build'!R15 | S32: =S9*Inputs_Scenarios!$C$5/S5+S31 | T32: =T9*Inputs_Scenarios!$C$5/T5+T31 | U32: =U9*Inputs_Scenarios!$C$5/U5+U31 | V32: =V9*Inputs_Scenarios!$C$5/V5+V31
A33: act_ng_rnd | B33: RND non-GAAP spend | S33: =S16-S19 | T33: =T16-T19 | U33: =U16-U19 | V33: =V16-V19
A34: act_cph_rnd | B34: RND non-GAAP spend per employee | S34: =S33/S27 | T34: =T33/T27 | U34: =U33/U27 | V34: =V33/V27
A35: act_ng_snm | B35: SNM non-GAAP spend | S35: =S17-S20 | T35: =T17-T20 | U35: =U17-U20 | V35: =V17-V20
A36: act_cph_snm | B36: SNM non-GAAP spend per employee | S36: =S35/S27 | T36: =T35/T27 | U36: =U35/U27 | V36: =V35/V27
A37: act_ng_gna | B37: GNA non-GAAP spend | S37: =S18-S21 | T37: =T18-T21 | U37: =U18-U21 | V37: =V18-V21
A38: act_cph_gna | B38: GNA non-GAAP spend per employee | S38: =S37/S27 | T38: =T37/T27 | U38: =U37/U27 | V38: =V37/V27
A39: act_ng_op | B39: Non-GAAP operating income (model definition) | S39: =S30-S12-S13+S14+S15-S33-S35-S37+S22 | T39: =T30-T12-T13+T14+T15-T33-T35-T37+T22 | U39: =U30-U12-U13+U14+U15-U33-U35-U37+U22 | V39: =V30-V12-V13+V14+V15-V33-V35-V37+V22
A40: act_fcf | B40: Free cash flow | S40: =S23-S24 | T40: =T23-T24 | U40: =U23-U24 | V40: =V23-V24
A41: act_conv | B41: FCF / non-GAAP operating income | S41: =S40/S39 | T41: =T40/T39 | U41: =U40/U39 | V41: =V40/V39
...

Sheet Unit_Economics_ROI
A1: Unit economics (trailing 4 quarters) and the GTM capital-allocation case
B2: Fiscal label | D2: Q4 FY22 | E2: Q1 FY23 | F2: Q2 FY23 | G2: Q3 FY23 | H2: Q4 FY23 | I2: Q1 FY24 | J2: Q2 FY24 | K2: Q3 FY24 | L2: Q4 FY24 | M2: Q1 FY25 | N2: Q2 FY25 | O2: Q3 FY25 | P2: Q4 FY25 | Q2: Q1 FY26 | R2: Q2 FY26 | S2: Q3 FY26 | T2: Q4 FY26 | U2: Q1 FY27 | V2: Q2 FY27
B3: Period end | D3: 2022-01-31 | E3: 2022-04-30 | F3: 2022-07-31 | G3: 2022-10-31 | H3: 2023-01-31 | I3: 2023-04-30 | J3: 2023-07-31 | K3: 2023-10-31 | L3: 2024-01-31 | M3: 2024-04-30 | N3: 2024-07-31 | O3: 2024-10-31 | P3: 2025-01-31 | Q3: 2025-04-30 | R3: 2025-07-31 | S3: 2025-10-31 | T3: 2026-01-31 | U3: 2026-04-30 | V3: 2026-07-31
B4: Kind | D4: Actual | E4: Actual | F4: Actual | G4: Actual | H4: Actual | I4: Actual | J4: Actual | K4: Actual | L4: Actual | M4: Actual | N4: Actual | O4: Actual | P4: Actual | Q4: Actual | R4: Actual | S4: Forecast | T4: Forecast | U4: Forecast | V4: Forecast
B5: Days | D5: 92 | E5: 89 | F5: 92 | G5: 92 | H5: 92 | I5: 89 | J5: 92 | K5: 92 | L5: 92 | M5: 90 | N5: 92 | O5: 92 | P5: 92 | Q5: 89 | R5: 92 | S5: 92 | T5: 92 | U5: 89 | V5: 92
B6: Fiscal q | D6: 4 | E6: 1 | F6: 2 | G6: 3 | H6: 4 | I6: 1 | J6: 2 | K6: 3 | L6: 4 | M6: 1 | N6: 2 | O6: 3 | P6: 4 | Q6: 1 | R6: 2 | S6: 3 | T6: 4 | U6: 1 | V6: 2
A8: h_ue | B8: A. SaaS efficiency scorecard (history: actuals as of cutoff; forecast: selected scenario)
A9: ue_snm_ng | B9: Non-GAAP sales and marketing | D9: ='Operating_Model'!D25-'Operating_Model'!D22 | E9: ='Operating_Model'!E25-'Operating_Model'!E22 | F9: ='Operating_Model'!F25-'Operating_Model'!F22 | G9: ='Operating_Model'!G25-'Operating_Model'!G22 | H9: ='Operating_Model'!H25-'Operating_Model'!H22 | I9: ='Operating_Model'!I25-'Operating_Model'!I22 | J9: ='Operating_Model'!J25-'Operating_Model'!J22 | K9: ='Operating_Model'!K25-'Operating_Model'!K22 | ... V9: ='Operating_Model'!V25-'Operating_Model'!V22
A10: ue_snm_ng_ttm | B10: Non-GAAP S&M, trailing 4Q | G10: =SUM(D9:G9) | H10: =SUM(E9:H9) | I10: =SUM(F9:I9) | J10: =SUM(G9:J9) | K10: =SUM(H9:K9) | L10: =SUM(I9:L9) | M10: =SUM(J9:M9) | N10: =SUM(K9:N9) | ... V10: =SUM(S9:V9)
A11: ue_sub_ttm | B11: Subscription revenue, trailing 4Q | G11: =SUM('Operating_Model'!D10:G10) | H11: =SUM('Operating_Model'!E10:H10) | I11: =SUM('Operating_Model'!F10:I10) | J11: =SUM('Operating_Model'!G10:J10) | K11: =SUM('Operating_Model'!H10:K10) | L11: =SUM('Operating_Model'!I10:L10) | M11: =SUM('Operating_Model'!J10:M10) | N11: =SUM('Operating_Model'!K10:N10) | ... V11: =SUM('Operating_Model'!S10:V10)
A12: ue_rev_ttm | B12: Revenue, trailing 4Q | G12: =SUM('Operating_Model'!D12:G12) | H12: =SUM('Operating_Model'!E12:H12) | I12: =SUM('Operating_Model'!F12:I12) | J12: =SUM('Operating_Model'!G12:J12) | K12: =SUM('Operating_Model'!H12:K12) | L12: =SUM('Operating_Model'!I12:L12) | M12: =SUM('Operating_Model'!J12:M12) | N12: =SUM('Operating_Model'!K12:N12) | ... V12: =SUM('Operating_Model'!S12:V12)
A13: ue_fcf_ttm | B13: FCF, trailing 4Q | G13: =SUM('Operating_Model'!D37:G37) | H13: =SUM('Operating_Model'!E37:H37) | I13: =SUM('Operating_Model'!F37:I37) | J13: =SUM('Operating_Model'!G37:J37) | K13: =SUM('Operating_Model'!H37:K37) | L13: =SUM('Operating_Model'!I37:L37) | M13: =SUM('Operating_Model'!J37:M37) | N13: =SUM('Operating_Model'!K37:N37) | ... V13: =SUM('Operating_Model'!S37:V37)
A14: ue_sub_gm_ng | B14: Non-GAAP subscription gross margin | D14: =('Operating_Model'!D10-'Operating_Model'!D14+'Operating_Model'!D19)/'Operating_Model'!D10 | E14: =('Operating_Model'!E10-'Operating_Model'!E14+'Operating_Model'!E19)/'Operating_Model'!E10 | F14: =('Operating_Model'!F10-'Operating_Model'!F14+'Operating_Model'!F19)/'Operating_Model'!F10 | G14: =('Operating_Model'!G10-'Operating_Model'!G14+'Operating_Model'!G19)/'Operating_Model'!G10 | H14: =('Operating_Model'!H10-'Operating_Model'!H14+'Operating_Model'!H19)/'Operating_Model'!H10 | I14: =('Operating_Model'!I10-'Operating_Model'!I14+'Operating_Model'!I19)/'Operating_Model'!I10 | J14: =('Operating_Model'!J10-'Operating_Model'!J14+'Operating_Model'!J19)/'Operating_Model'!J10 | K14: =('Operating_Model'!K10-'Operating_Model'!K14+'Operating_Model'!K19)/'Operating_Model'!K10 | ... V14: =('Operating_Model'!V10-'Operating_Model'!V14+'Operating_Model'!V19)/'Operating_Model'!V10
A15: ue_arr | B15: ARR proxy | G15: ='Cohort_ARR_Build'!G15 | H15: ='Cohort_ARR_Build'!H15 | I15: ='Cohort_ARR_Build'!I15 | J15: ='Cohort_ARR_Build'!J15 | K15: ='Cohort_ARR_Build'!K15 | L15: ='Cohort_ARR_Build'!L15 | M15: ='Cohort_ARR_Build'!M15 | N15: ='Cohort_ARR_Build'!N15 | ... V15: ='Cohort_ARR_Build'!V15
A16: ue_nnarr | B16: Net new ARR, trailing 4Q | K16: =K15-G15 | L16: =L15-H15 | M16: =M15-I15 | N16: =N15-J15 | O16: =O15-K15 | P16: =P15-L15 | Q16: =Q15-M15 | R16: =R15-N15 | ... V16: =V15-R15
A17: ue_cac_payback | B17: CAC payback (months) | K17: =J10/(K16*K14)*Inputs_Scenarios!$C$7 | L17: =K10/(L16*L14)*Inputs_Scenarios!$C$7 | M17: =L10/(M16*M14)*Inputs_Scenarios!$C$7 | N17: =M10/(N16*N14)*Inputs_Scenarios!$C$7 | O17: =N10/(O16*O14)*Inputs_Scenarios!$C$7 | P17: =O10/(P16*P14)*Inputs_Scenarios!$C$7 | Q17: =P10/(Q16*Q14)*Inputs_Scenarios!$C$7 | R17: =Q10/(R16*R14)*Inputs_Scenarios!$C$7 | ... V17: =U10/(V16*V14)*Inputs_Scenarios!$C$7
A18: ue_magic | B18: Magic number | K18: =(K11-G11)/J10 | L18: =(L11-H11)/K10 | M18: =(M11-I11)/L10 | N18: =(N11-J11)/M10 | O18: =(O11-K11)/N10 | P18: =(P11-L11)/O10 | Q18: =(Q11-M11)/P10 | R18: =(R11-N11)/Q10 | ... V18: =(V11-R11)/U10
A19: ue_rule40 | B19: Rule of 40 (revenue growth YoY + FCF margin TTM) | H19: ='Operating_Model'!H13+H13/H12 | I19: ='Operating_Model'!I13+I13/I12 | J19: ='Operating_Model'!J13+J13/J12 | K19: ='Operating_Model'!K13+K13/K12 | L19: ='Operating_Model'!L13+L13/L12 | M19: ='Operating_Model'!M13+M13/M12 | N19: ='Operating_Model'!N13+N13/N12 | O19: ='Operating_Model'!O13+O13/O12 | ... V19: ='Operating_Model'!V13+V13/V12
A20: ue_burn | B20: Burn multiple (only while FCF is negative) | K20: =IF(K13<0,-K13/K16,"n/m") | L20: =IF(L13<0,-L13/L16,"n/m") | M20: =IF(M13<0,-M13/M16,"n/m") | N20: =IF(N13<0,-N13/N16,"n/m") | O20: =IF(O13<0,-O13/O16,"n/m") | P20: =IF(P13<0,-P13/P16,"n/m") | Q20: =IF(Q13<0,-Q13/Q16,"n/m") | R20: =IF(R13<0,-R13/R16,"n/m") | ... V20: =IF(V13<0,-V13/V16,"n/m")
A21: ue_nrr | B21: Net ARR expansion rate | G21: ='Cohort_ARR_Build'!G18 | H21: ='Cohort_ARR_Build'!H18 | I21: ='Cohort_ARR_Build'!I18 | J21: ='Cohort_ARR_Build'!J18 | K21: ='Cohort_ARR_Build'!K18 | L21: ='Cohort_ARR_Build'!L18 | M21: ='Cohort_ARR_Build'!M18 | N21: ='Cohort_ARR_Build'!N18 | ... V21: ='Cohort_ARR_Build'!V18
A22: ue_new_logos_ttm | B22: New logos, trailing 4Q [Calibrated Synthetic] | K22: =SUM('Cohort_ARR_Build'!H10:K10) | L22: =SUM('Cohort_ARR_Build'!I10:L10) | M22: =SUM('Cohort_ARR_Build'!J10:M10) | N22: =SUM('Cohort_ARR_Build'!K10:N10) | O22: =SUM('Cohort_ARR_Build'!L10:O10) | P22: =SUM('Cohort_ARR_Build'!M10:P10) | Q22: =SUM('Cohort_ARR_Build'!N10:Q10) | R22: =SUM('Cohort_ARR_Build'!O10:R10) | ... V22: =SUM('Cohort_ARR_Build'!S10:V10)
A23: ue_cac_logo | B23: Non-GAAP S&M per new logo | K23: =J10/K22 | L23: =K10/L22 | M23: =L10/M22 | N23: =M10/N22 | O23: =N10/O22 | P23: =O10/P22 | Q23: =P10/Q22 | R23: =Q10/R22 | ... V23: =U10/V22
A24: ue_ltv | B24: LTV per customer [Illustrative: assumed churn] | G24: ='Cohort_ARR_Build'!G15/'Cohort_ARR_Build'!G8*G14/(1-(1-Inputs_Scenarios!$F$14)^Inputs_Scenarios!$C$6) | H24: ='Cohort_ARR_Build'!H15/'Cohort_ARR_Build'!H8*H14/(1-(1-Inputs_Scenarios!$F$14)^Inputs_Scenarios!$C$6) | I24: ='Cohort_ARR_Build'!I15/'Cohort_ARR_Build'!I8*I14/(1-(1-Inputs_Scenarios!$F$14)^Inputs_Scenarios!$C$6) | J24: ='Cohort_ARR_Build'!J15/'Cohort_ARR_Build'!J8*J14/(1-(1-Inputs_Scenarios!$F$14)^Inputs_Scenarios!$C$6) | K24: ='Cohort_ARR_Build'!K15/'Cohort_ARR_Build'!K8*K14/(1-(1-Inputs_Scenarios!$F$14)^Inputs_Scenarios!$C$6) | L24: ='Cohort_ARR_Build'!L15/'Cohort_ARR_Build'!L8*L14/(1-(1-Inputs_Scenarios!$F$14)^Inputs_Scenarios!$C$6) | M24: ='Cohort_ARR_Build'!M15/'Cohort_ARR_Build'!M8*M14/(1-(1-Inputs_Scenarios!$F$14)^Inputs_Scenarios!$C$6) | N24: ='Cohort_ARR_Build'!N15/'Cohort_ARR_Build'!N8*N14/(1-(1-Inputs_Scenarios!$F$14)^Inputs_Scenarios!$C$6) | ... V24: ='Cohort_ARR_Build'!V15/'Cohort_ARR_Build'!V8*V14/(1-(1-Inputs_Scenarios!$F$14)^Inputs_Scenarios!$C$6)
A25: ue_ltv_cac | B25: LTV : CAC [Illustrative] | K25: =K24/K23 | L25: =L24/L23 | M25: =M24/M23 | N25: =N24/N23 | O25: =O24/O23 | P25: =P24/P23 | Q25: =Q24/Q23 | R25: =R24/R23 | ... V25: =V24/V23
A27: B. GTM capital allocation: 30 Enterprise AEs (A) vs product attach (B), monthly, inputs on Inputs_Scenarios [mostly Illustrative]
A28: roi_month | B28: Month | D28: 1 | E28: 2 | F28: 3 | G28: 4 | H28: 5 | I28: 6 | J28: 7 | K28: 8 | L28: 9 | M28: 10 | N28: 11 | O28: 12 | P28: 13 | Q28: 14 | R28: 15 | S28: 16 | T28: 17 | U28: 18 | V28: 19 | W28: 20 | X28: 21 | Y28: 22 | Z28: 23 | AA28: 24 | AB28: 25 | AC28: 26 | AD28: 27 | AE28: 28 | AF28: 29 | AG28: 30 | AH28: 31 | AI28: 32 | AJ28: 33 | AK28: 34 | AL28: 35 | AM28: 36
A29: roi_g_m | B29: Monthly net expansion of new ARR | D29: =Inputs_Scenarios!$F$48^(1/Inputs_Scenarios!$C$7)-1 | E29: =Inputs_Scenarios!$F$48^(1/Inputs_Scenarios!$C$7)-1 | F29: =Inputs_Scenarios!$F$48^(1/Inputs_Scenarios!$C$7)-1 | G29: =Inputs_Scenarios!$F$48^(1/Inputs_Scenarios!$C$7)-1 | H29: =Inputs_Scenarios!$F$48^(1/Inputs_Scenarios!$C$7)-1 | I29: =Inputs_Scenarios!$F$48^(1/Inputs_Scenarios!$C$7)-1 | J29: =Inputs_Scenarios!$F$48^(1/Inputs_Scenarios!$C$7)-1 | K29: =Inputs_Scenarios!$F$48^(1/Inputs_Scenarios!$C$7)-1 | ... AM29: =Inputs_Scenarios!$F$48^(1/Inputs_Scenarios!$C$7)-1
A30: a_ramp | B30: A: ramp | D30: =MIN(1,D28/Inputs_Scenarios!$F$40) | E30: =MIN(1,E28/Inputs_Scenarios!$F$40) | F30: =MIN(1,F28/Inputs_Scenarios!$F$40) | G30: =MIN(1,G28/Inputs_Scenarios!$F$40) | H30: =MIN(1,H28/Inputs_Scenarios!$F$40) | I30: =MIN(1,I28/Inputs_Scenarios!$F$40) | J30: =MIN(1,J28/Inputs_Scenarios!$F$40) | K30: =MIN(1,K28/Inputs_Scenarios!$F$40) | ... AM30: =MIN(1,AM28/Inputs_Scenarios!$F$40)
A31: a_booked | B31: A: new ARR booked | D31: =Inputs_Scenarios!$F$35*Inputs_Scenarios!$F$38/Inputs_Scenarios!$C$7*Inputs_Scenarios!$F$39*D30 | E31: =Inputs_Scenarios!$F$35*Inputs_Scenarios!$F$38/Inputs_Scenarios!$C$7*Inputs_Scenarios!$F$39*E30 | F31: =Inputs_Scenarios!$F$35*Inputs_Scenarios!$F$38/Inputs_Scenarios!$C$7*Inputs_Scenarios!$F$39*F30 | G31: =Inputs_Scenarios!$F$35*Inputs_Scenarios!$F$38/Inputs_Scenarios!$C$7*Inputs_Scenarios!$F$39*G30 | H31: =Inputs_Scenarios!$F$35*Inputs_Scenarios!$F$38/Inputs_Scenarios!$C$7*Inputs_Scenarios!$F$39*H30 | I31: =Inputs_Scenarios!$F$35*Inputs_Scenarios!$F$38/Inputs_Scenarios!$C$7*Inputs_Scenarios!$F$39*I30 | J31: =Inputs_Scenarios!$F$35*Inputs_Scenarios!$F$38/Inputs_Scenarios!$C$7*Inputs_Scenarios!$F$39*J30 | K31: =Inputs_Scenarios!$F$35*Inputs_Scenarios!$F$38/Inputs_Scenarios!$C$7*Inputs_Scenarios!$F$39*K30 | ... AM31: =Inputs_Scenarios!$F$35*Inputs_Scenarios!$F$38/Inputs_Scenarios!$C$7*Inputs_Scenarios!$F$39*AM30
A32: a_arr | B32: A: ARR | D32: =D31 | E32: =D32*(1+E29)+E31 | F32: =E32*(1+F29)+F31 | G32: =F32*(1+G29)+G31 | H32: =G32*(1+H29)+H31 | I32: =H32*(1+I29)+I31 | J32: =I32*(1+J29)+J31 | K32: =J32*(1+K29)+K31 | L32: =K32*(1+L29)+L31 | ... AM32: =AL32*(1+AM29)+AM31
A33: a_gp | B33: A: gross profit | D33: =D32/Inputs_Scenarios!$C$7*Inputs_Scenarios!$F$49 | E33: =E32/Inputs_Scenarios!$C$7*Inputs_Scenarios!$F$49 | F33: =F32/Inputs_Scenarios!$C$7*Inputs_Scenarios!$F$49 | G33: =G32/Inputs_Scenarios!$C$7*Inputs_Scenarios!$F$49 | H33: =H32/Inputs_Scenarios!$C$7*Inputs_Scenarios!$F$49 | I33: =I32/Inputs_Scenarios!$C$7*Inputs_Scenarios!$F$49 | J33: =J32/Inputs_Scenarios!$C$7*Inputs_Scenarios!$F$49 | K33: =K32/Inputs_Scenarios!$C$7*Inputs_Scenarios!$F$49 | ... AM33: =AM32/Inputs_Scenarios!$C$7*Inputs_Scenarios!$F$49
A34: a_cost | B34: A: AE cost + overhead + commission | D34: =Inputs_Scenarios!$F$35*Inputs_Scenarios!$F$36/Inputs_Scenarios!$C$7*(1+Inputs_Scenarios!$F$37)+Inputs_Scenarios!$F$41*D31 | E34: =Inputs_Scenarios!$F$35*Inputs_Scenarios!$F$36/Inputs_Scenarios!$C$7*(1+Inputs_Scenarios!$F$37)+Inputs_Scenarios!$F$41*E31 | F34: =Inputs_Scenarios!$F$35*Inputs_Scenarios!$F$36/Inputs_Scenarios!$C$7*(1+Inputs_Scenarios!$F$37)+Inputs_Scenarios!$F$41*F31 | G34: =Inputs_Scenarios!$F$35*Inputs_Scenarios!$F$36/Inputs_Scenarios!$C$7*(1+Inputs_Scenarios!$F$37)+Inputs_Scenarios!$F$41*G31 | H34: =Inputs_Scenarios!$F$35*Inputs_Scenarios!$F$36/Inputs_Scenarios!$C$7*(1+Inputs_Scenarios!$F$37)+Inputs_Scenarios!$F$41*H31 | I34: =Inputs_Scenarios!$F$35*Inputs_Scenarios!$F$36/Inputs_Scenarios!$C$7*(1+Inputs_Scenarios!$F$37)+Inputs_Scenarios!$F$41*I31 | J34: =Inputs_Scenarios!$F$35*Inputs_Scenarios!$F$36/Inputs_Scenarios!$C$7*(1+Inputs_Scenarios!$F$37)+Inputs_Scenarios!$F$41*J31 | K34: =Inputs_Scenarios!$F$35*Inputs_Scenarios!$F$36/Inputs_Scenarios!$C$7*(1+Inputs_Scenarios!$F$37)+Inputs_Scenarios!$F$41*K31 | ... AM34: =Inputs_Scenarios!$F$35*Inputs_Scenarios!$F$36/Inputs_Scenarios!$C$7*(1+Inputs_Scenarios!$F$37)+Inputs_Scenarios!$F$41*AM31
A35: a_net | B35: A: net cash flow | D35: =D33-D34 | E35: =E33-E34 | F35: =F33-F34 | G35: =G33-G34 | H35: =H33-H34 | I35: =I33-I34 | J35: =J33-J34 | K35: =K33-K34 | ... AM35: =AM33-AM34
A36: a_cum | B36: A: cumulative | D36: =D35 | E36: =D36+E35 | F36: =E36+F35 | G36: =F36+G35 | H36: =G36+H35 | I36: =H36+I35 | J36: =I36+J35 | K36: =J36+K35 | L36: =K36+L35 | ... AM36: =AL36+AM35
A37: b_adopt | B37: B: adoption | D37: =MIN(1,D28/Inputs_Scenarios!$F$45) | E37: =MIN(1,E28/Inputs_Scenarios!$F$45) | F37: =MIN(1,F28/Inputs_Scenarios!$F$45) | G37: =MIN(1,G28/Inputs_Scenarios!$F$45) | H37: =MIN(1,H28/Inputs_Scenarios!$F$45) | I37: =MIN(1,I28/Inputs_Scenarios!$F$45) | J37: =MIN(1,J28/Inputs_Scenarios!$F$45) | K37: =MIN(1,K28/Inputs_Scenarios!$F$45) | ... AM37: =MIN(1,AM28/Inputs_Scenarios!$F$45)
A38: b_target | B38: B: attach ARR target | D38: =Inputs_Scenarios!$F$42*Inputs_Scenarios!$F$43*Inputs_Scenarios!$F$44*D37 | E38: =Inputs_Scenarios!$F$42*Inputs_Scenarios!$F$43*Inputs_Scenarios!$F$44*E37 | F38: =Inputs_Scenarios!$F$42*Inputs_Scenarios!$F$43*Inputs_Scenarios!$F$44*F37 | G38: =Inputs_Scenarios!$F$42*Inputs_Scenarios!$F$43*Inputs_Scenarios!$F$44*G37 | H38: =Inputs_Scenarios!$F$42*Inputs_Scenarios!$F$43*Inputs_Scenarios!$F$44*H37 | I38: =Inputs_Scenarios!$F$42*Inputs_Scenarios!$F$43*Inputs_Scenarios!$F$44*I37 | J38: =Inputs_Scenarios!$F$42*Inputs_Scenarios!$F$43*Inputs_Scenarios!$F$44*J37 | K38: =Inputs_Scenarios!$F$42*Inputs_Scenarios!$F$43*Inputs_Scenarios!$F$44*K37 | ... AM38: =Inputs_Scenarios!$F$42*Inputs_Scenarios!$F$43*Inputs_Scenarios!$F$44*AM37
A39: b_added | B39: B: new ARR added | D39: =MAX(0,D38) | E39: =MAX(0,E38-D38) | F39: =MAX(0,F38-E38) | G39: =MAX(0,G38-F38) | H39: =MAX(0,H38-G38) | I39: =MAX(0,I38-H38) | J39: =MAX(0,J38-I38) | K39: =MAX(0,K38-J38) | L39: =MAX(0,L38-K38) | ... AM39: =MAX(0,AM38-AL38)
A40: b_arr | B40: B: ARR | D40: =D39 | E40: =D40*(1+E29)+E39 | F40: =E40*(1+F29)+F39 | G40: =F40*(1+G29)+G39 | H40: =G40*(1+H29)+H39 | I40: =H40*(1+I29)+I39 | J40: =I40*(1+J29)+J39 | K40: =J40*(1+K29)+K39 | L40: =K40*(1+L29)+L39 | ... AM40: =AL40*(1+AM29)+AM39
A41: b_gp | B41: B: gross profit | D41: =D40/Inputs_Scenarios!$C$7*Inputs_Scenarios!$F$49 | E41: =E40/Inputs_Scenarios!$C$7*Inputs_Scenarios!$F$49 | F41: =F40/Inputs_Scenarios!$C$7*Inputs_Scenarios!$F$49 | G41: =G40/Inputs_Scenarios!$C$7*Inputs_Scenarios!$F$49 | H41: =H40/Inputs_Scenarios!$C$7*Inputs_Scenarios!$F$49 | I41: =I40/Inputs_Scenarios!$C$7*Inputs_Scenarios!$F$49 | J41: =J40/Inputs_Scenarios!$C$7*Inputs_Scenarios!$F$49 | K41: =K40/Inputs_Scenarios!$C$7*Inputs_Scenarios!$F$49 | ... AM41: =AM40/Inputs_Scenarios!$C$7*Inputs_Scenarios!$F$49
A42: b_cost | B42: B: build + run cost | D42: =Inputs_Scenarios!$F$47+Inputs_Scenarios!$F$46 | E42: =Inputs_Scenarios!$F$47 | F42: =Inputs_Scenarios!$F$47 | G42: =Inputs_Scenarios!$F$47 | H42: =Inputs_Scenarios!$F$47 | I42: =Inputs_Scenarios!$F$47 | J42: =Inputs_Scenarios!$F$47 | K42: =Inputs_Scenarios!$F$47 | L42: =Inputs_Scenarios!$F$47 | ... AM42: =Inputs_Scenarios!$F$47
...

Sheet Checks
A1: Checks (each row: largest absolute difference across its quarters; PASS within tolerance)
A3: Check | B3: Max |diff| | C3: Result
A4: GAAP operating income = as reported (history) | B4: =SUMPRODUCT(ABS(E4:S4)) | C4: =IF(B4<=Inputs_Scenarios!$C$8,"PASS","FAIL") | E4: ='Operating_Model'!D28-'Operating_Model'!D29 | F4: ='Operating_Model'!E28-'Operating_Model'!E29 | G4: ='Operating_Model'!F28-'Operating_Model'!F29 | H4: ='Operating_Model'!G28-'Operating_Model'!G29 | I4: ='Operating_Model'!H28-'Operating_Model'!H29 | J4: ='Operating_Model'!I28-'Operating_Model'!I29 | K4: ='Operating_Model'!J28-'Operating_Model'!J29 | L4: ='Operating_Model'!K28-'Operating_Model'!K29 | ... S4: ='Operating_Model'!R28-'Operating_Model'!R29
A5: ARR proxy = cohort ledger ARR (history) | B5: =SUMPRODUCT(ABS(H5:S5)) | C5: =IF(B5<=Inputs_Scenarios!$C$8,"PASS","FAIL") | H5: ='Cohort_ARR_Build'!G15-'Cohort_ARR_Build'!G19 | I5: ='Cohort_ARR_Build'!H15-'Cohort_ARR_Build'!H19 | J5: ='Cohort_ARR_Build'!I15-'Cohort_ARR_Build'!I19 | K5: ='Cohort_ARR_Build'!J15-'Cohort_ARR_Build'!J19 | L5: ='Cohort_ARR_Build'!K15-'Cohort_ARR_Build'!K19 | M5: ='Cohort_ARR_Build'!L15-'Cohort_ARR_Build'!L19 | N5: ='Cohort_ARR_Build'!M15-'Cohort_ARR_Build'!M19 | O5: ='Cohort_ARR_Build'!N15-'Cohort_ARR_Build'!N19 | ... S5: ='Cohort_ARR_Build'!R15-'Cohort_ARR_Build'!R19
A6: Revenue = Atlas + EA + Services | B6: =SUMPRODUCT(ABS(E6:W6)) | C6: =IF(B6<=Inputs_Scenarios!$C$8,"PASS","FAIL") | E6: ='Operating_Model'!D12-'Operating_Model'!D8-'Operating_Model'!D9-'Operating_Model'!D11 | F6: ='Operating_Model'!E12-'Operating_Model'!E8-'Operating_Model'!E9-'Operating_Model'!E11 | G6: ='Operating_Model'!F12-'Operating_Model'!F8-'Operating_Model'!F9-'Operating_Model'!F11 | H6: ='Operating_Model'!G12-'Operating_Model'!G8-'Operating_Model'!G9-'Operating_Model'!G11 | I6: ='Operating_Model'!H12-'Operating_Model'!H8-'Operating_Model'!H9-'Operating_Model'!H11 | J6: ='Operating_Model'!I12-'Operating_Model'!I8-'Operating_Model'!I9-'Operating_Model'!I11 | K6: ='Operating_Model'!J12-'Operating_Model'!J8-'Operating_Model'!J9-'Operating_Model'!J11 | L6: ='Operating_Model'!K12-'Operating_Model'!K8-'Operating_Model'!K9-'Operating_Model'!K11 | ... W6: ='Operating_Model'!V12-'Operating_Model'!V8-'Operating_Model'!V9-'Operating_Model'!V11
A7: Non-GAAP op. income = GAAP + SBC + amortization | B7: =SUMPRODUCT(ABS(E7:W7)) | C7: =IF(B7<=Inputs_Scenarios!$C$8,"PASS","FAIL") | E7: ='Operating_Model'!D33-'Operating_Model'!D28-'Operating_Model'!D31-'Operating_Model'!D32 | F7: ='Operating_Model'!E33-'Operating_Model'!E28-'Operating_Model'!E31-'Operating_Model'!E32 | G7: ='Operating_Model'!F33-'Operating_Model'!F28-'Operating_Model'!F31-'Operating_Model'!F32 | H7: ='Operating_Model'!G33-'Operating_Model'!G28-'Operating_Model'!G31-'Operating_Model'!G32 | I7: ='Operating_Model'!H33-'Operating_Model'!H28-'Operating_Model'!H31-'Operating_Model'!H32 | J7: ='Operating_Model'!I33-'Operating_Model'!I28-'Operating_Model'!I31-'Operating_Model'!I32 | K7: ='Operating_Model'!J33-'Operating_Model'!J28-'Operating_Model'!J31-'Operating_Model'!J32 | L7: ='Operating_Model'!K33-'Operating_Model'!K28-'Operating_Model'!K31-'Operating_Model'!K32 | ... W7: ='Operating_Model'!V33-'Operating_Model'!V28-'Operating_Model'!V31-'Operating_Model'!V32
A8: Opex = non-GAAP spend + SBC | B8: =SUMPRODUCT(ABS(H8:W8)) | C8: =IF(B8<=Inputs_Scenarios!$C$8,"PASS","FAIL") | H8: ='Operating_Model'!G27-'Headcount_Opex_Build'!G16-'Operating_Model'!G21-'Operating_Model'!G22-'Operating_Model'!G23 | I8: ='Operating_Model'!H27-'Headcount_Opex_Build'!H16-'Operating_Model'!H21-'Operating_Model'!H22-'Operating_Model'!H23 | J8: ='Operating_Model'!I27-'Headcount_Opex_Build'!I16-'Operating_Model'!I21-'Operating_Model'!I22-'Operating_Model'!I23 | K8: ='Operating_Model'!J27-'Headcount_Opex_Build'!J16-'Operating_Model'!J21-'Operating_Model'!J22-'Operating_Model'!J23 | L8: ='Operating_Model'!K27-'Headcount_Opex_Build'!K16-'Operating_Model'!K21-'Operating_Model'!K22-'Operating_Model'!K23 | M8: ='Operating_Model'!L27-'Headcount_Opex_Build'!L16-'Operating_Model'!L21-'Operating_Model'!L22-'Operating_Model'!L23 | N8: ='Operating_Model'!M27-'Headcount_Opex_Build'!M16-'Operating_Model'!M21-'Operating_Model'!M22-'Operating_Model'!M23 | O8: ='Operating_Model'!N27-'Headcount_Opex_Build'!N16-'Operating_Model'!N21-'Operating_Model'!N22-'Operating_Model'!N23 | ... W8: ='Operating_Model'!V27-'Headcount_Opex_Build'!V16-'Operating_Model'!V21-'Operating_Model'!V22-'Operating_Model'!V23
A9: Forecast ARR = existing + new | B9: =SUMPRODUCT(ABS(T9:W9)) | C9: =IF(B9<=Inputs_Scenarios!$C$8,"PASS","FAIL") | T9: ='Cohort_ARR_Build'!S15-'Cohort_ARR_Build'!S13-'Cohort_ARR_Build'!S14 | U9: ='Cohort_ARR_Build'!T15-'Cohort_ARR_Build'!T13-'Cohort_ARR_Build'!T14 | V9: ='Cohort_ARR_Build'!U15-'Cohort_ARR_Build'!U13-'Cohort_ARR_Build'!U14 | W9: ='Cohort_ARR_Build'!V15-'Cohort_ARR_Build'!V13-'Cohort_ARR_Build'!V14

Sheet Sources
A1: Sources: every historical input, with the SEC filing it came from (as known at the cutoff)
A3: line | B3: fiscal_label | C3: period_end | D3: value | E3: derivation | F3: source_accn | G3: filed
A4: amort_intangibles | B4: Q4 FY22 | C4: 2022-01-31 | D4: 2300000 | E4: fy_minus_9m | F4: 0001441816-24-000049 - 0001441816-22-000193 | G4: 2024-03-15
A5: amort_intangibles | B5: Q1 FY23 | C5: 2022-04-30 | D5: 2300000 | E5: reported_3m | F5: 0001441816-23-000087 | G5: 2023-06-02
A6: amort_intangibles | B6: Q2 FY23 | C6: 2022-07-31 | D6: 2300000 | E6: reported_3m | F6: 0001441816-23-000168 | G6: 2023-09-01
A7: amort_intangibles | B7: Q3 FY23 | C7: 2022-10-31 | D7: 2300000 | E7: reported_3m | F7: 0001441816-23-000248 | G7: 2023-12-07
A8: amort_intangibles | B8: Q4 FY23 | C8: 2023-01-31 | D8: 2300000 | E8: fy_minus_9m | F8: 0001441816-25-000057 - 0001441816-23-000248 | G8: 2025-03-21
A9: amort_intangibles | B9: Q1 FY24 | C9: 2023-04-30 | D9: 2300000 | E9: reported_3m | F9: 0001441816-24-000111 | G9: 2024-05-31
A10: amort_intangibles | B10: Q2 FY24 | C10: 2023-07-31 | D10: 2300000 | E10: reported_3m | F10: 0001441816-24-000188 | G10: 2024-08-30
A11: amort_intangibles | B11: Q3 FY24 | C11: 2023-10-31 | D11: 2800000 | E11: reported_3m | F11: 0001441816-24-000260 | G11: 2024-12-10
A12: amort_intangibles | B12: Q4 FY24 | C12: 2024-01-31 | D12: 3200000 | E12: fy_minus_9m | F12: 0001441816-25-000057 - 0001441816-24-000260 | G12: 2025-03-21
A13: amort_intangibles | B13: Q1 FY25 | C13: 2024-04-30 | D13: 2700000 | E13: reported_3m | F13: 0001441816-25-000118 | G13: 2025-06-04
A14: amort_intangibles | B14: Q2 FY25 | C14: 2024-07-31 | D14: 100000 | E14: reported_3m | F14: 0001441816-24-000188 | G14: 2024-08-30
A15: amort_intangibles | B15: Q3 FY25 | C15: 2024-10-31 | D15: 200000 | E15: reported_3m | F15: 0001441816-24-000260 | G15: 2024-12-10
... A419: snm | B419: Q2 FY26 | C419: 2025-07-31 | D419: 244065000 | E419: reported_3m | F419: 0001441816-25-000181 | G419: 2025-08-27
